Workbook

Sheet HIPOTESIS NEGOCIO EN MARCHA
B10: Cuando se dice que una entidad es un negocio en marcha se quiere decir que tiene la capacidad de continuar operando, por lo menos, durante un período adicional después de la fecha sobre la que informa. La hipótesis de negocio en marcha no puede ser una especulación o presunción, pues la norma establece que la entidad debe “evaluar la capacidad de continuar como un negocio en marcha al final de cada período”. Esto significa que deben documentarse las condiciones que permitan concluir (o probar) que la entidad tiene capacidad de seguir operando.
C12: Evaluación de la hipótesis de negocio en marcha
B14: Por lo menos una vez al año la entidad debe elaborar un memorando de evaluación de negocio en marcha para tener evidencia de la capacidad operativa y de la utilización de los Estándares Internacionales.
C17: Situaciones que dan indicio de incumplimiento de la hipótesis de negocio en marcha
C21: Posición patrimonial negativo
C22: Realización de préstamos a corto plazo para solucionar el pago de cuotas a largo plazo
C23: Perder apoyo y credibilidad con el sector financiero
C24: Indicadores financieros desfavorables
C25: Atraso en pagos de dividendos
C26: Incumplimiento de las obligaciones contractuales
C27: Retiro de empleados sin vincular nuevos
C28: Incumplimiento de requerimientos legales
C30: El anexo 5 del DUR 2420 de 2015 establece el marco técnico de elaboración de los estados financieros para las empresas que no cumplen con el principio de negocio en marcha; al respecto, su párrafo 7 establece:
C31: Cuando la administración de la entidad, al realizar esta evaluación, sea consciente de la existencia de incertidumbres importantes, relativas a eventos o condiciones que puedan aportar dudas significativas sobre la posibilidad de que la entidad siga funcionando normalmente, procederá a revelarlas en los estados financieros. Adicionalmente, cuando una entidad no prepare los estados financieros bajo la hipótesis de negocio en marcha, revelará ese hecho, junto con las hipótesis sobre las que han sido elaborados y las razones por las que la entidad no se considera como un negocio en marcha.

Sheet BP
C2: BALANCE DE PRUEBA CONTABLE
D4: HOJA DE TRABAJO
B5: Cuenta | C5: Concepto | D5: Saldo inicial | E5: Debe | F5: Haber | G5: Saldo final
B6: 11 | C6: Efectivo y Equivalentes | D6: =SUM(D7:D10) -> 72900000 | E6: =SUM(E7:E10) -> 0 | F6: =SUM(F7:F10) -> 0 | G6: =SUM(G7:G10) -> 72900000
B7: 1105 | C7: Caja | D7: 500000 | G7: =+D7+E7-F7 -> 500000
B8: 1110 | C8: Bancos | D8: 32400000 | G8: =+D8+E8-F8 -> 32400000
B9: 1150 | C9: Efectivo restringido | D9: 15000000 | G9: =+D9+E9-F9 -> 15000000
B10: 1190 | C10: Equivalentes al efectivo | D10: 25000000 | G10: =+D10+E10-F10 -> 25000000
B11: 12 | C11: Inversiones | D11: =+D12+D19+D22 -> 70000000 | E11: =+E12+E19+E22 -> 3000000 | F11: =+F12+F19+F22 -> 0 | G11: =+G12+G19+G22 -> 73000000
B12: 1205 | C12: Inversiones al Valor Razonable (Instrumentos Financieros) | D12: =+D13+D14 -> 50000000 | E12: =+E13+E14 -> 3000000 | F12: =+F13+F14 -> 0 | G12: =+G13+G14 -> 53000000
B13: 1205XX | C13: Costo de Adquisición | D13: 50000000 | G13: =+D13+E13-F13 -> 50000000
B14: 1205xxxx | C14: Diferencia por mediciones al valor razonable | D14: 0 | E14: =+INVERSIONES!D38 -> 3000000 | G14: =+D14+E14-F14 -> 3000000
B15: 1210 | C15: Inversiones al Valor Razonable (Asociadas) | D15: =+D16+D17+D18 -> 0 | E15: =+E16+E17+E18 -> 0 | F15: =+F16+F17+F18 -> 0 | G15: =+G16+G17+G18 -> 0
B16: 1210xx | C16: Costo de Adquisición | D16: 0 | G16: =+D16+E16-F16 -> 0
B17: 1210xxxx | C17: Diferencia por mediciones al valor razonable | D17: 0 | G17: =+D17+E17-F17 -> 0
B18: 1210xxxx | C18: Método departicipación | D18: 0 | G18: =+D18+E18-F18 -> 0
B19: 1250 | C19: Inversiones al Costo Amortizado (CDT) | D19: =+D20+D21 -> 20000000 | E19: =+E20+E21 -> 0 | F19: =+F20+F21 -> 0 | G19: =+G20+G21 -> 20000000
B20: 1250xx | C20: Costo de Adquisición | D20: 20000000 | G20: =+D20+E20-F20 -> 20000000
B21: 1250xxxx | C21: Diferencia por medición al costo amortizado | E21: 0 | G21: =+D21+E21-F21 -> 0
B22: 1299 | C22: Deterioro de Inversiones | D22: =+D23 -> 0 | G22: =+D22+E22-F22 -> 0
B23: 1299xx | C23: Deterioro | G23: =+D23+E23-F23 -> 0
B24: 13 | C24: Deudores | D24: =+D25+D29+D34+D27 -> 115700000 | E24: =+E25+E29+E34+E27 -> 0 | F24: =+F25+F29+F34+F27 -> 6000000 | G24: =+G25+G29+G34+G27 -> 109700000
B25: 1305 | C25: Clientes | D25: =+D26 -> 65000000 | E25: =+E26 -> 0 | F25: =+F26 -> 0 | G25: =+G26 -> 65000000
B26: 1305xx | C26: Nacionales | D26: 65000000 | E26: 0 | G26: =+D26+E26-F26 -> 65000000
B27: 1325 | C27: A Socios y/o Accionistas | D27: =+D28 -> 30000000 | E27: =+E28 -> 0 | F27: =+F28 -> 0 | G27: =+G28 -> 30000000
B28: 1325xx | C28: A Socios | D28: 30000000 | G28: =+D28+E28-F28 -> 30000000
B29: 1355 | C29: Anticipo de impuestos | D29: =SUM(D30:D33) -> 20700000 | E29: =SUM(E30:E33) -> 0 | F29: =SUM(F30:F33) -> 0 | G29: =SUM(G30:G33) -> 20700000
B30: 1355xx | C30: Retenciones en la fuente | D30: 17500000 | E30: 0 | F30: 0 | G30: =+D30+E30-F30 -> 17500000
B31: 1355xx | C31: Autorretenciones | D31: 3200000 | F31: 0 | G31: =+D31+E31-F31 -> 3200000
B32: 1355xxx | C32: Saldo a favor 2022 | E32: 0 | G32: =+D32+E32-F32 -> 0
B33: 1355XX | C33: Descuentos tributarios | E33: 0 | F33: 0 | G33: =+D33+E33-F33 -> 0
B34: 1399 | C34: Deterioro De Cartera | D34: =+D35 -> 0 | E34: =+E35 -> 0 | F34: =+F35 -> 6000000 | G34: =+G35 -> -6000000
B35: 1399xx | C35: De Clientes | E35: 0 | F35: =+CXC!J27 -> 6000000 | G35: =+D35+E35-F35 -> -6000000
B36: 14 | C36: Inventarios | D36: =+D37+D38 -> 78500000 | E36: =+E37+E38 -> 0 | F36: =+F37+F38 -> 11775000 | G36: =+G37+G38 -> 66725000
B37: 1435 | C37: Producto No Fabricado Por La Entidad | D37: 78500000 | G37: =+D37+E37-F37 -> 78500000
B38: 1499 | C38: Deterioro Inventario | D38: 0 | F38: =+INVENTARIOS!D23 -> 11775000 | G38: =+D38+E38-F38 -> -11775000
B39: 15 | C39: Propiedades Planta y Equipo | D39: =+D40+D43+D46+D49+D51+D55 -> 684000000 | E39: =+E40+E43+E46+E49+E51+E55 -> 130000000 | F39: =+F40+F43+F46+F49+F51+F55 -> 18000000 | G39: =+G40+G43+G46+G49+G51+G55 -> 796000000
B40: 1508 | C40: Terreno | D40: =+D41+D42 -> 100000000 | E40: =+E41+E42 -> 80000000 | F40: =+F41+F42 -> 0 | G40: =+G41+G42 -> 180000000
B41: 150805 | C41: Costo Terreno | D41: 100000000 | G41: =+D41+E41-F41 -> 100000000
B42: 150810 | C42: Valor revaluación del Terreno | D42: 0 | E42: =+PPYE!C5 -> 80000000 | G42: =+D42+E42-F42 -> 80000000
...

Sheet REQUISITOS DE PROCEDENCIA DE CO
D3: LISTADO DE REQUISITOS PARA DEPURAR EL IMPUESTO CORRIENTE
D5: REQUISITOS GENERALES
D6: ART 107 DEL ET: | F6: NECESIDAD , PROPORCIONALIDAD, Y CAUSALIDAD.
D7: PRUEBA DOCUMENTAL:¨ | E7: Art 771-2 del et
F8: factura electrónica | I8: LA FACTURA PUEDE TENER FECHA DEL PERIODO SIGUIENTE, LO IMPORTANTE ES PODER PROBAR QUE EL BIEN O EL SERVICIO SE RECIBIÓ EN EL 2024.
F9: Documento equivalente
F10: Documento soprote: NE , DSOCJNOAEF
D12: BANCARIZACIÓN:¨ | F12: ART 771-5 DEL ET.. | H12: PAGOS INDIVIDUALES SUPERIORES A 100 UVT.
H13: =100*47000 -> 4700000
H15: CARLOS TAPIAS
H16: 2000000 | K16: 3000000
D19: REQUISITOS PARTICULARES
D20: 107-1 Del ET | F20: 0.01
D21: 108 del ET | F21: AL DIA CON LA SEGURIDAD SOCIAL Y PARAFISCALES. | J21: ART 115-1 DEL ET
F22: EXIGIR LA SEGRIDAD SOCIAL A LOS INDEPENDIENTES:¨ UNICAMENTE LOS QUE EL VALOR DEL SERVICIO SEA MAYOR A 1 SMLMV
D23: Retención en la fuente como requisito de procedencia:¨
H24: Salarios
H25: Pagos a la casa matriz
H26: Pagos a proveedores domiciliados en paraisos fiscales
D28: RUT:¨ | E28: ART 177 - 2 DEL ET | G28: RUT EN OPERACIONES GRAVADAS CON NO RESPONSABLES DE IVA.
D30: ACEPTACIONES:¨ ART 616 -1 ACUSES DE RECIBO. | H30: OPERACIONES A PLAZO
G31: RECIBI BIENES Y SERVICIOS | J31: NADA TIENE QUE VER CON EL RADIAN
G32: RECIBÍ LA FACTURA | J32: NO TIENE NADAQ QUE VER CON EL RADIAN
J33: EL RADIAN NO ES UN REQUISITO DE PROCEDENCIA DE COSTOS
J34: NO CONFUNDIR EL RADIAN

Sheet INVERSIONES
B3: En Activos | C3: Base fiscal > Base contable | D3: Deducible | E3: IDACTIVO
B4: En Activos | C4: Base fiscal < Base contable | D4: Imponible | E4: IDPASIVO
B5: En Pasivos | C5: Base fiscal > Base contable | D5: Imponible | E5: IDPASIVO
B6: En Pasivos | C6: Base fiscal < Base contable | D6: Deducible | E6: IDACTIVO
B12: 12 | C12: Inversiones | D12: =+D13+D20+D23 -> 74000000
B13: 1205 | C13: Inversiones al Valor Razonable (Instrumentos Financieros) | D13: =+D14+D15 -> 53000000
B14: 1205XX | C14: Costo de Adquisición | D14: 50000000 | E14: El E.T. SÓLO PERMITE EL COSTO
B15: 1205xxxx | C15: Diferencia por mediciones al valor razonable | D15: =+D38 -> 3000000
B16: 1210 | C16: Inversiones al Valor Razonable (Asociadas) | D16: =+D17+D18+D19 -> 0
B17: 1210xx | C17: Costo de Adquisición | D17: 0
B18: 1210xxxx | C18: Diferencia por mediciones al valor razonable | D18: 0
B19: 1210xxxx | C19: Método departicipación | D19: 0
B20: 1250 | C20: Inversiones al Costo Amortizado (CDT) | D20: =+D21+D22 -> 21000000
B21: 1250xx | C21: Costo de Adquisición | D21: 20000000 | E21: El E.T. SÓLO PERMITE EL COSTO
B22: 1250xxxx | C22: Diferencia por medición al costo amortizado | D22: =+D35 -> 1000000
B23: 1299 | C23: Deterioro de Inversiones | D23: =+D24 -> 0
B24: 1299xx | C24: Deterioro
D28: 1000 | E28: ACCIONES
D29: =+D14/D28 -> 50000
C30: 45657 | D30: 53000
D31: =+D30*D28 -> 53000000
C34: INGRESOS POR INTERESE CA | E34: 1000000
C35: =+C22 -> Diferencia por medición al costo amortizado | D35: =+E34 -> 1000000
C37: INGRESO POR INVERS MVR | E37: =+D31-D14 -> 3000000
C38: =+C15 -> Diferencia por mediciones al valor razonable | D38: =+E37 -> 3000000
C41: VALOR CONTABLE | D41: =+D12 -> 74000000
C42: VALOR FISCAL | D42: =+D12-D15 -> 71000000
C43: DIFERENCIA | D43: =+D41-D42 -> 3000000
D44: =+D43*E45 -> 450000 | E44: IMPUESTO DIFERIDO PASIVO
D45: 0.35 | E45: 0.15
B47: En Activos | C47: Base fiscal > Base contable | D47: Deducible | E47: IDACTIVO
B48: En Activos | C48: Base fiscal < Base contable | D48: Imponible | E48: IDPASIVO
B49: En Pasivos | C49: Base fiscal > Base contable | D49: Imponible | E49: IDPASIVO
B50: En Pasivos | C50: Base fiscal < Base contable | D50: Deducible | E50: IDACTIVO
B53: 5410 | C53: GASTO IMPUESTO DIFERIDO | D53: =+D44 -> 450000
B54: 27 | C54: IMPUESTO DIFERIDO PASIVO | E54: =+D44 -> 450000

Sheet CXC
B5: 13 | C5: Deudores | D5: =+D6 -> 65000000
B6: 1305 | C6: Clientes | D6: =+D7 -> 65000000
B7: 1305xx | C7: Nacionales | D7: 65000000
D9: 0 | E9: 0.05 | F9: 0.1 | G9: 0.15
D10: 0-3 MESES | E10: 3-6MESES | F10: 6-12 MESES | G10: MAS DE 12 MESES
B11: A | C11: 15000000 | D11: 0 | E11: 9000000 | G11: 6000000
B12: B | C12: 8000000 | D12: =+C12 -> 8000000
B13: C | C13: 12000000 | D13: 10000000 | E13: =+C13-D13 -> 2000000
B14: D | C14: 17000000 | D14: 15000000 | F14: =+C14-D14 -> 2000000
B15: E | C15: 13000000 | D15: =+C15 -> 13000000
C16: =SUM(C11:C15) -> 65000000 | D16: =SUM(D11:D15) -> 46000000 | E16: =SUM(E11:E15) -> 11000000 | F16: =SUM(F11:F15) -> 2000000 | G16: =SUM(G11:G15) -> 6000000
E17: =+E9*E16 -> 550000 | F17: =+F9*F16 -> 200000 | G17: =+G9*G16 -> 900000 | H17: =SUM(E17:G17) -> 1650000
H18: =+G16*0.33 -> 1980000
C20: EL CLIENTE A TIENE PROBLEMAS ECONOMICOS Y SE ESTIMA QUE EL 40% NO LO VA A PAGAR
C22: =+C11*0.4 -> 6000000 | D22: DETERIORO
H23: GASTO PROVISION | I23: =+H18 -> 1980000
D24: contable | E24: fiscal | H24: PROVISION CARTERA | J24: =+I23 -> 1980000
C25: =+C7 -> Nacionales | D25: =+D6 -> 65000000 | E25: =+D25 -> 65000000
C26: deterioro | D26: =+I26 -> 6000000 | E26: =+I23 -> 1980000 | H26: GASTO DETERIORO | I26: =+C11*0.4 -> 6000000
D27: =+D25-D26 -> 59000000 | E27: =+E25-E26 -> 63020000 | F27: IDA | H27: DET DE CXC | J27: =+I26 -> 6000000
E28: =+E27-D27 -> 4020000 | F28: DIFERENCIA
D29: 0.35 | E29: =+E28*D29 -> 1407000 | F29: TARIFA
C31: En Activos | D31: Base fiscal > Base contable | E31: Deducible | F31: IDACTIVO
C32: En Activos | D32: Base fiscal < Base contable | E32: Imponible | F32: IDPASIVO
C33: En Pasivos | D33: Base fiscal > Base contable | E33: Imponible | F33: IDPASIVO
C34: En Pasivos | D34: Base fiscal < Base contable | E34: Deducible | F34: IDACTIVO
C37: 5410 | D37: GASTO IMPUESTO DIFERIDO | F37: =+E38 -> 1407000
C38: 17 | D38: IMPUESTO DIFERIDO ACTIVO | E38: =+E29 -> 1407000

Sheet INVENTARIOS
B2: 14 | C2: Inventarios | D2: =+D3+D4 -> 78500000
B3: 1435 | C3: Producto No Fabricado Por La Entidad | D3: 78500000
B4: 1499 | C4: Deterioro Inventario | D4: 0
C7: DETERIORO DEL INVENTARIO 15% | D7: =+D3*15% -> 11775000
C9: GASTO DETERIORO | D9: =+D7 -> 11775000
C10: DETERIORO DE INVENTARIOS | E10: =+D9 -> 11775000
C13: RECUERDA QUE : ART 64 E.T.
C16: 1. Cuando se trate de faltantes de inventarios de fácil destrucción o pérdida, las unidades del inventario final pueden disminuirse hasta en un tres por ciento (3%) de la suma del inventario inicial más las compras. Si se demostrare la ocurrencia de hechos constitutivos de fuerza mayor o caso fortuito, pueden aceptarse disminuciones mayores.
C18: 2. Los inventarios dados de baja por obsolescencia y debidamente destruidos, reciclados o chatarrizados; siempre y cuando sean diferentes a los previstos en el numeral 1 de este artículo, serán deducibles del impuesto sobre la renta y complementarios en su precio de adquisición, más costos directamente atribuibles y costos de transformación en caso de que sean aplicables. Para la aceptación de esta disminución de inventarios se requiere como mínimo un documento donde conste la siguiente información: cantidad, descripción del producto, costo fiscal unitario y total y justificación de la obsolescencia o destrucción, debidamente firmado por el representante legal o quien haga sus veces y las personas responsables de tal destrucción y demás pruebas que sean pertinentes.
D21: CONTABLE | E21: FISCAL
C22: Producto No Fabricado Por La Entidad | D22: =+D2 -> 78500000 | E22: =+D22 -> 78500000
C23: Deterioro Inventario | D23: =+D9 -> 11775000 | E23: 0
D24: =+D22-D23 -> 66725000 | E24: =+E22-E23 -> 78500000
E25: =+E24-D24 -> 11775000 | F25: 0.35 | G25: =+E25*F25 -> 4121250
C27: En Activos | D27: Base fiscal > Base contable | E27: Deducible | F27: IDACTIVO
C28: En Activos | D28: Base fiscal < Base contable | E28: Imponible | F28: IDPASIVO
C29: En Pasivos | D29: Base fiscal > Base contable | E29: Imponible | F29: IDPASIVO
C30: En Pasivos | D30: Base fiscal < Base contable | E30: Deducible | F30: IDACTIVO
B33: 54XXX | C33: GASTO IMPUESTO DIFERIDO | E33: =+G25 -> 4121250
B34: XXX 17 | C34: IMP DIFERIDO ACTIVO | D34: =+G25 -> 4121250

Sheet PPYE
A3: 1508 | B3: Terreno | C3: =+C4+C5 -> 180000000
A4: 150805 | B4: Costo Terreno | C4: 100000000
A5: 150810 | B5: Valor revaluación del Terreno | C5: =+C36 -> 80000000
A6: 1516 | B6: Edificaciones | C6: =+C7+C8 -> 450000000
A7: 151605 | B7: Costo edificaciones | C7: 400000000
A8: 151610 | B8: Valor revaluación de la edificaciones | C8: =+C37 -> 50000000
A9: 1520 | B9: Maquinaria Y Equipo | C9: =+C10+C11 -> 119000000
A10: 152005 | B10: Costo Maquinaria | C10: 100000000
A11: 1520xx | B11: Iva en Compra de Maquinaria | C11: 19000000
A12: 1540 | B12: Flota Y Equipo De Transporte | C12: =+C13 -> 65000000
A13: 154005 | B13: Vehículo | C13: 65000000
A14: 1592 | B14: Depreciación Acumulada | C14: =+C15+C16+C17 -> 0 | E14: COSTO ADQUIS + MEJORAS
A15: 159216 | B15: Edificaciones | C15: 0 | E15: MENOS DEP Y DETERIORO
A16: 159220 | B16: Maquinaria y Equipo | C16: 0
A17: 159240 | B17: Flota y Equipo de Transporte | C17: 0
A18: 1599 | B18: Deterioro de Propiedad Planta y Equipo | C18: =+C19+C20+C21 -> 0
A19: 1599xx | B19: Edificaciones | C19: 0
A20: 1599xx | B20: Maquinaria y Equipo | C20: 0
A21: 1599xx | B21: Flota y Equipo de Transporte | C21: 0
B23: TERRENO VR | C23: 180000000
B24: EDIFICIO VR | C24: 450000000
D25: DEPREC. CONTABLE | E25: DEPREC. FISCAL
B26: MAQUINARIA | C26: 20 | D26: =+C10/C26 -> 5000000 | E26: =+C10/10 -> 10000000
B27: VEHICULO | C27: 10 | D27: =+C12/C27 -> 6500000 | E27: =+C13/C27 -> 6500000
B28: VALOR EN MERCADO | C28: 52000000
B29: VALOR CONTABLE | C29: =+C13-D27 -> 58500000
B30: DETERIORO | C30: =+C29-C28 -> 6500000
B32: GASTO DETERIORO | C32: =+C30 -> 6500000
B33: DETERIORO VEHICULO | D33: =+C31+C32 -> 6500000
B36: =+B5 -> Valor revaluación del Terreno | C36: =+C23-C4 -> 80000000
B37: =+B8 -> Valor revaluación de la edificaciones | C37: =+C24-C7 -> 50000000
B38: Superavit por valoroizacion | D38: =+C36+C37 -> 130000000
C40: TERRENO | D40: EDIFICIO
B41: VALOR CONTABLE | C41: =+C3 -> 180000000 | D41: =+C6 -> 450000000
B42: VALOR FISCAL | C42: =+C4 -> 100000000 | D42: =+C7 -> 400000000
B43: DIFERENCIA | C43: =+C41-C42 -> 80000000 | D43: =+D41-D42 -> 50000000
B44: 0.15 | C44: =+C43*B44 -> 12000000 | D44: =+D43*B44 -> 7500000
B46: En Activos | C46: Base fiscal > Base contable | D46: Deducible | E46: IDACTIVO
B47: En Activos | C47: Base fiscal < Base contable | D47: Imponible | E47: IDPASIVO
B48: En Pasivos | C48: Base fiscal > Base contable | D48: Imponible | E48: IDPASIVO
...

Sheet PASIVO
A2: 22 | B2: Proveedores | C2: =+C3 -> 120000000
A3: 2205 | B3: Proveedores | C3: =+C4+C5 -> 120000000
A4: 2205xx | B4: Nacionales | C4: 75000000
A5: 2205xx | B5: Del exterior | C5: 45000000
B10: Del exterior | C10: 45000000
C12: =+C10/4500 -> 10000 | D12: USD
C13: 4500 | D13: CADA DÓLAR
B15: 45291 | C15: 4800 | D15: EL DÓLAR
B16: DEUDA A DIC | C16: =+C12*C15 -> 48000000
C19: GASTO POR DIF EN CAMBIO | D19: =+C16-C10 -> 3000000
C20: PROVEEDORES DEL EXTERIOR | E20: =+D19 -> 3000000
C24: VALOR CONTABLE | D24: =+C5+E20 -> 48000000
C25: VALOR FISCAL | D25: =+C5 -> 45000000 | E25: 0.35
C26: DIFERENCIA | D26: =+D24-D25 -> 3000000 | E26: =+D26*E25 -> 1050000
B28: En Pasivos | C28: Base fiscal > Base contable | D28: Imponible | E28: IDPASIVO
B29: En Pasivos | C29: Base fiscal < Base contable | D29: Deducible | E29: IDACTIVO
B32: 54 | C32: GASTO IMP DIFERIDO | E32: =+E26 -> 1050000
B33: 17 | C33: IMPUESTO DIFERIDO ACTIVO | D33: =+E32 -> 1050000

Sheet DETERMINACION IMP DIF
A2: 1. Impuestos diferidos provenientes de diferencias temporarias
A4: Fila | B4: Concepto | D4: Base contable | E4: Base Fiscal | F4: Diferencia Temporaria | G4: Diferencia Permanente | H4: Saldo impuesto diferido a 31 -DIC vigencia actual | I4: Saldo impuesto diferido a 31 -DIC vigencia anterior | J4: Variación | K4: Tasa fiscal aplicada
A6: 12 | B6: Activo (Diferencias temporarias deducibles)
A7: =A6+1 -> 13 | C7: Efectivo y equivalentes al efectivo | F7: =+D7-E7 -> 0 | H7: =+F7 -> 0 | I7: 0 | J7: =I7-H7 -> 0 | K7: =IF(F7=" ",0,IF(F7=0,0,H7/F7)) -> 0
A8: =A7+1 -> 14 | C8: Inversiones e instrumentos derivados | F8: =+D8-E8 -> 0 | H8: 0 | I8: 0 | J8: =I8-H8 -> 0 | K8: =IF(F8=" ",0,IF(F8=0,0,H8/F8)) -> 0
A9: =A8+1 -> 15 | C9: Cuentas por cobrar | D9: =+CXC!D27 -> 59000000 | E9: =+CXC!E27 -> 63020000 | F9: =+D9-E9 -> -4020000 | H9: =+CXC!E29 -> 1407000 | I9: 0 | J9: =+H9-I9 -> 1407000 | K9: =IF(F9=" ",0,IF(F9=0,0,H9/F9)) -> -0.35
A10: =A9+1 -> 16 | C10: Inventarios | D10: =+INVENTARIOS!D24 -> 66725000 | E10: =+INVENTARIOS!E24 -> 78500000 | F10: =+D10-E10 -> -11775000 | H10: =+INVENTARIOS!G25 -> 4121250 | I10: 0 | J10: =+H10-I10 -> 4121250 | K10: =IF(F10=" ",0,IF(F10=0,0,H10/F10)) -> -0.35
A11: =A10+1 -> 17 | C11: Propiedades, planta y equipo | D11: =+PPYE!C57+PPYE!D57 -> 147000000 | E11: =+PPYE!C58+PPYE!D58 -> 153500000 | F11: =+D11-E11 -> -6500000 | H11: =+PPYE!D61 -> 975000 | I11: 0 | J11: =+H11-I11 -> 975000 | K11: =IF(F11=" ",0,IF(F11=0,0,H11/F11)) -> -0.15
A12: =A11+1 -> 18 | C12: Activos intangibles | F12: =+D12-E12 -> 0 | I12: 0 | J12: =+H12-I12 -> 0 | K12: =IF(F12=" ",0,IF(F12=0,0,H12/F12)) -> 0
A13: =A12+1 -> 19 | C13: Propiedades de inversión | F13: =+D13-E13 -> 0 | I13: 0 | J13: =+H13-I13 -> 0 | K13: =IF(F13=" ",0,IF(F13=0,0,H13/F13)) -> 0
A14: =A13+1 -> 20 | C14: Activos biológicos | F14: =+D14-E14 -> 0 | I14: 0 | J14: =+H14-I14 -> 0 | K14: =IF(F14=" ",0,IF(F14=0,0,H14/F14)) -> 0
A15: =A14+1 -> 21 | C15: Activos no corrientes mantenidos para la venta / entregar a propietarios | F15: =+D15-E15 -> 0 | I15: 0 | J15: =+H15-I15 -> 0 | K15: =IF(F15=" ",0,IF(F15=0,0,H15/F15)) -> 0
A16: =A15+1 -> 22 | C16: Pasivos financieros y cuentas por pagar | D16: =+PASIVO!D24 -> 48000000 | E16: =+PASIVO!D25 -> 45000000 | F16: =+D16-E16 -> 3000000 | H16: =+PASIVO!E26 -> 1050000 | I16: 0 | J16: =+H16-I16 -> 1050000 | K16: =IF(F16=" ",0,IF(F16=0,0,H16/F16)) -> 0.35
A17: =A16+1 -> 23 | C17: Impuestos, gravámenes y tasas | D17: 0 | E17: 0 | F17: =+D17-E17 -> 0 | H17: =+F17 -> 0 | I17: 0 | J17: =+H17-I17 -> 0 | K17: =IF(F17=" ",0,IF(F17=0,0,H17/F17)) -> 0
A18: =A17+1 -> 24 | C18: Beneficios a Empleados | D18: 0 | E18: 0 | F18: =+D18-E18 -> 0 | H18: =+F18 -> 0 | I18: 0 | J18: =+H18-I18 -> 0 | K18: =IF(F18=" ",0,IF(F18=0,0,H18/F18)) -> 0
A19: =A18+1 -> 25 | C19: Provisiones | D19: 0 | E19: 0 | F19: =+D19-E19 -> 0 | H19: =+F19 -> 0 | I19: 0 | J19: =+H19-I19 -> 0 | K19: =IF(F19=" ",0,IF(F19=0,0,H19/F19)) -> 0
A20: =A19+1 -> 26 | C20: Otros Pasivos Anticipos y avances recibidos | D20: 0 | E20: 0 | F20: =+D20-E20 -> 0 | H20: =+F20 -> 0 | I20: 0 | J20: =+H20-I20 -> 0 | K20: =IF(F20=" ",0,IF(F20=0,0,H20/F20)) -> 0
A21: =A20+1 -> 27 | C21: Operaciones con títulos y derivados | D21: 0 | E21: 0 | F21: =+D21-E21 -> 0 | H21: =+F21 -> 0 | I21: 0 | J21: =+H21-I21 -> 0 | K21: =IF(F21=" ",0,IF(F21=0,0,H21/F21)) -> 0
A22: =A21+1 -> 28 | C22: Perdidas fiscales y/o excesos de renta presuntiva | D22: 0 | E22: 0 | F22: =+D22-E22 -> 0 | H22: =+F22 -> 0 | I22: 0 | J22: =+H22-I22 -> 0 | K22: =IF(F22=" ",0,IF(F22=0,0,H22/F22)) -> 0
A23: =A22+1 -> 29 | C23: Activos reconocidos solamente para fines fiscales | D23: 0 | E23: 0 | F23: =+D23-E23 -> 0 | H23: =+F23 -> 0 | I23: 0 | J23: =+H23-I23 -> 0 | K23: =IF(F23=" ",0,IF(F23=0,0,H23/F23)) -> 0
A24: =A23+1 -> 30 | C24: Otros activos | D24: 0 | E24: 0 | F24: =+D24-E24 -> 0 | H24: =+F24 -> 0 | I24: 0 | J24: =I24-H24 -> 0 | K24: =IF(F24=" ",0,IF(F24=0,0,H24/F24)) -> 0
A25: =A24+1 -> 31 | C25: Valor total | D25: =SUM(D7:D24) -> 320725000 | E25: =SUM(E7:E24) -> 340020000 | H25: =SUM(H7:H24) -> 7553250 | I25: =SUM(I7:I24) -> 0 | J25: =SUM(J7:J24) -> 7553250
A26: =A25+1 -> 32 | B26: Pasivo (Diferencias temporarias imponibles)
A27: =A26+1 -> 33 | C27: Efectivo y equivalentes al efectivo | J27: =I27-H27 -> 0 | K27: =IF(F27=" ",0,IF(F27=0,0,H27/F27)) -> 0
A28: =A27+1 -> 34 | C28: Inversiones e instrumentos derivados | D28: =+INVERSIONES!D41 -> 74000000 | E28: =+INVERSIONES!D42 -> 71000000 | F28: =+D28-E28 -> 3000000 | H28: =+INVERSIONES!D44 -> 450000 | I28: 0 | J28: =+H28-I28 -> 450000 | K28: =IF(F28=" ",0,IF(F28=0,0,H28/F28)) -> 0.15
A29: =A28+1 -> 35 | C29: Cuentas por cobrar | F29: =+D29-E29 -> 0 | J29: =+H29-I29 -> 0 | K29: =IF(F29=" ",0,IF(F29=0,0,H29/F29)) -> 0
A30: =A29+1 -> 36 | C30: Inventarios | F30: =+D30-E30 -> 0 | J30: =+H30-I30 -> 0 | K30: =IF(F30=" ",0,IF(F30=0,0,H30/F30)) -> 0
A31: =A30+1 -> 37 | C31: Propiedades, planta y equipo | D31: =+PPYE!C41+PPYE!D41 -> 630000000 | E31: =+PPYE!C42+PPYE!D42 -> 500000000 | F31: =+D31-E31 -> 130000000 | H31: =+PPYE!C44+PPYE!D44 -> 19500000 | J31: =+H31-I31 -> 19500000 | K31: =IF(F31=" ",0,IF(F31=0,0,H31/F31)) -> 0.15
A32: =A31+1 -> 38 | C32: Activos intangibles | J32: =+H32-I32 -> 0 | K32: =IF(F32=" ",0,IF(F32=0,0,H32/F32)) -> 0
A33: =A32+1 -> 39 | C33: Propiedades de inversión | J33: =+H33-I33 -> 0 | K33: =IF(F33=" ",0,IF(F33=0,0,H33/F33)) -> 0
A34: =A33+1 -> 40 | C34: Activos biológicos | J34: =+H34-I34 -> 0 | K34: =IF(F34=" ",0,IF(F34=0,0,H34/F34)) -> 0
A35: =A34+1 -> 41 | C35: Activos no corrientes mantenidos para la venta / entregar a propietarios | J35: =I35-H35 -> 0 | K35: =IF(F35=" ",0,IF(F35=0,0,H35/F35)) -> 0
A36: =A35+1 -> 42 | C36: Pasivos financieros y cuentas por pagar | F36: =+D36-E36 -> 0 | H36: =+F36 -> 0 | J36: =I36-H36 -> 0 | K36: =IF(F36=" ",0,IF(F36=0,0,H36/F36)) -> 0
A37: =A36+1 -> 43 | C37: Impuestos, gravámenes y tasas | F37: =+D37-E37 -> 0 | H37: =+F37 -> 0 | J37: =I37-H37 -> 0 | K37: =IF(F37=" ",0,IF(F37=0,0,H37/F37)) -> 0
A38: =A37+1 -> 44 | C38: Beneficios a Empleados | D38: 0 | E38: 0 | F38: =+D38-E38 -> 0 | H38: =+F38 -> 0 | J38: =I38-H38 -> 0 | K38: =IF(F38=" ",0,IF(F38=0,0,H38/F38)) -> 0
A39: =A38+1 -> 45 | C39: Provisiones | F39: =+D39-E39 -> 0 | H39: =+F39 -> 0 | J39: =I39-H39 -> 0 | K39: =IF(F39=" ",0,IF(F39=0,0,H39/F39)) -> 0
A40: =A39+1 -> 46 | C40: Otros Pasivos Anticipos y avances recibidos | F40: =+D40-E40 -> 0 | H40: =+F40 -> 0 | J40: =I40-H40 -> 0 | K40: =IF(F40=" ",0,IF(F40=0,0,H40/F40)) -> 0
A41: =A40+1 -> 47 | C41: Operaciones con títulos y derivados | F41: =+D41-E41 -> 0 | H41: =+F41 -> 0 | J41: =I41-H41 -> 0 | K41: =IF(F41=" ",0,IF(F41=0,0,H41/F41)) -> 0
A42: =A41+1 -> 48 | C42: Perdidas fiscales y/o excesos de renta presuntiva | F42: =+D42-E42 -> 0 | H42: =+F42 -> 0 | J42: =I42-H42 -> 0 | K42: =IF(F42=" ",0,IF(F42=0,0,H42/F42)) -> 0
A43: =A42+1 -> 49 | C43: Activos reconocidos solamente para fines fiscales | F43: =+D43-E43 -> 0 | H43: =+F43 -> 0 | J43: =I43-H43 -> 0 | K43: =IF(F43=" ",0,IF(F43=0,0,H43/F43)) -> 0
...

Sheet DETERMINACION IMP CTE
C2: BALANCE DE PRUEBA FISCAL
D4: HOJA DE TRABAJO
B5: Cuenta | C5: Concepto | D5: Saldo inicial | E5: Debe | F5: Haber | G5: Saldo final
B6: 11 | C6: Efectivo y Equivalentes | D6: =SUM(D7:D10) -> 72900000 | E6: =SUM(E7:E10) -> 0 | F6: =SUM(F7:F10) -> 0 | G6: =SUM(G7:G10) -> 72900000
B7: 1105 | C7: Caja | D7: =+BP!G7 -> 500000 | G7: =+D7+E7-F7 -> 500000
B8: 1110 | C8: Bancos | D8: =+BP!G8 -> 32400000 | G8: =+D8+E8-F8 -> 32400000
B9: 1150 | C9: Efectivo restringido | D9: =+BP!G9 -> 15000000 | G9: =+D9+E9-F9 -> 15000000
B10: 1190 | C10: Equivalentes al efectivo | D10: =+BP!G10 -> 25000000 | G10: =+D10+E10-F10 -> 25000000
B11: 12 | C11: Inversiones | D11: =+D12+D19+D22 -> 73000000 | E11: =+E12+E19+E22 -> 0 | F11: =+F12+F19+F22 -> 3000000 | G11: =+G12+G19+G22 -> 70000000
B12: 1205 | C12: Inversiones al Valor Razonable (Instrumentos Financieros) | D12: =+D13+D14 -> 53000000 | E12: =+E13+E14 -> 0 | F12: =+F13+F14 -> 3000000 | G12: =+G13+G14 -> 50000000
B13: 1205XX | C13: Costo de Adquisición | D13: =+BP!G13 -> 50000000 | G13: =+D13+E13-F13 -> 50000000
B14: 1205xxxx | C14: Diferencia por mediciones al valor razonable | D14: =+BP!G14 -> 3000000 | E14: 0 | F14: =+D14 -> 3000000 | G14: =+D14+E14-F14 -> 0
B15: 1210 | C15: Inversiones al Valor Razonable (Asociadas) | D15: =+D16+D17+D18 -> 0 | E15: =+E16+E17+E18 -> 0 | F15: =+F16+F17+F18 -> 0 | G15: =+G16+G17+G18 -> 0
B16: 1210xx | C16: Costo de Adquisición | D16: =+BP!G16 -> 0 | G16: =+D16+E16-F16 -> 0
B17: 1210xxxx | C17: Diferencia por mediciones al valor razonable | D17: =+BP!G17 -> 0 | G17: =+D17+E17-F17 -> 0
B18: 1210xxxx | C18: Método departicipación | D18: =+BP!G18 -> 0 | G18: =+D18+E18-F18 -> 0
B19: 1250 | C19: Inversiones al Costo Amortizado (CDT) | D19: =+D20+D21 -> 20000000 | E19: =+E20+E21 -> 0 | F19: =+F20+F21 -> 0 | G19: =+G20+G21 -> 20000000
B20: 1250xx | C20: Costo de Adquisición | D20: =+BP!G20 -> 20000000 | G20: =+D20+E20-F20 -> 20000000
B21: 1250xxxx | C21: Diferencia por medición al costo amortizado | D21: =+BP!G21 -> 0 | E21: 0 | G21: =+D21+E21-F21 -> 0
B22: 1299 | C22: Deterioro de Inversiones | D22: =+D23 -> 0 | G22: =+D22+E22-F22 -> 0
B23: 1299xx | C23: Deterioro | D23: =+BP!G23 -> 0 | G23: =+D23+E23-F23 -> 0
B24: 13 | C24: Deudores | D24: =+D25+D29+D34+D27 -> 109700000 | E24: =+E25+E29+E34+E27 -> 6000000 | F24: =+F25+F29+F34+F27 -> 0 | G24: =+G25+G29+G34+G27 -> 115700000
B25: 1305 | C25: Clientes | D25: =+D26 -> 65000000 | E25: =+E26 -> 0 | F25: =+F26 -> 0 | G25: =+G26 -> 65000000
B26: 1305xx | C26: Nacionales | D26: =+BP!G26 -> 65000000 | E26: 0 | G26: =+D26+E26-F26 -> 65000000
B27: 1325 | C27: A Socios y/o Accionistas | D27: =+D28 -> 30000000 | E27: =+E28 -> 0 | F27: =+F28 -> 0 | G27: =+G28 -> 30000000
B28: 1325xx | C28: A Socios | D28: =+BP!G28 -> 30000000 | G28: =+D28+E28-F28 -> 30000000
B29: 1355 | C29: Anticipo de impuestos | D29: =SUM(D30:D33) -> 20700000 | E29: =SUM(E30:E33) -> 0 | F29: =SUM(F30:F33) -> 0 | G29: =SUM(G30:G33) -> 20700000
B30: 1355xx | C30: Retenciones en la fuente | D30: =+BP!G30 -> 17500000 | E30: 0 | F30: 0 | G30: =+D30+E30-F30 -> 17500000
B31: 1355xx | C31: Autorretenciones | D31: =+BP!G31 -> 3200000 | F31: 0 | G31: =+D31+E31-F31 -> 3200000
B32: 1355xxx | C32: Saldo a favor 2022 | D32: =+BP!G32 -> 0 | E32: 0 | G32: =+D32+E32-F32 -> 0
B33: 1355XX | C33: Descuentos tributarios | D33: =+BP!G33 -> 0 | E33: 0 | F33: 0 | G33: =+D33+E33-F33 -> 0
B34: 1399 | C34: Deterioro De Cartera | D34: =+D35 -> -6000000 | E34: =-D34 -> 6000000 | F34: =+F35 -> 0 | G34: =+D34+E34 -> 0
B35: 1399xx | C35: De Clientes | D35: =+BP!G35 -> -6000000 | E35: 0 | F35: 0 | G35: =+D35+E35-F35 -> -6000000
B36: 14 | C36: Inventarios | D36: =+D37+D38 -> 66725000 | E36: =+E37+E38 -> 11775000 | F36: =+F37+F38 -> 0 | G36: =+G37+G38 -> 78500000
B37: 1435 | C37: Producto No Fabricado Por La Entidad | D37: =+BP!G37 -> 78500000 | G37: =+D37+E37-F37 -> 78500000
B38: 1499 | C38: Deterioro Inventario | D38: =+BP!G38 -> -11775000 | E38: =-D38 -> 11775000 | F38: 0 | G38: =+D38+E38-F38 -> 0
B39: 15 | C39: Propiedades Planta y Equipo | D39: =+D40+D43+D46+D49+D51+D55 -> 796000000 | E39: =+E40+E43+E46+E49+E51+E55 -> 136500000 | F39: =+F40+F43+F46+F49+F51+F55 -> 11500000 | G39: =+G40+G43+G46+G49+G51+G55 -> 921000000
B40: 1508 | C40: Terreno | D40: =+D41+D42 -> 180000000 | E40: =+E41+E42 -> 80000000 | F40: =+F41+F42 -> 0 | G40: =+G41+G42 -> 260000000
B41: 150805 | C41: Costo Terreno | D41: =+BP!G41 -> 100000000 | G41: =+D41+E41-F41 -> 100000000
B42: 150810 | C42: Valor revaluación del Terreno | D42: =+BP!G42 -> 80000000 | E42: =+PPYE!C5 -> 80000000 | G42: =+D42+E42-F42 -> 160000000
...

Sheet E.R.I.

Sheet E.S.F.
